Workbook

Sheet README_SOPMaintenance skill 使用说
A1: 售后仓库台账操作SOP | B1: Warehouse After-Sales Ledger SOP | C1: AI操作入口 / AI Operation Entry
A2: 中文 | B2: English | C2: 处理ERP SH工单或打印Label前，必须先读取工作簿内对应AI_SKILL页。Skill页为最新业务规则来源，优先于聊天记忆。
A3: 编辑权限颜色说明 | B3: Editing Permission Colour Guide | C3: 工单/备货/出库 → AI_SKILL_工单读取
A4: 绿色：只有绿色标签工作表中的绿色单元格可以日常编辑。其他区域不得修改。 | B4: Green: Only green cells inside green-tab sheets may be edited during daily work. Do not change other areas. | C4: 打印Label → AI_SKILL_Label打印
A5: 黄色：黄色标签工作表是维护表，仅在产品、库位或动作规则需要更新时编辑。 | B5: Yellow: Yellow-tab sheets are maintenance tables. Edit only when product, location or action rules require maintenance. | C5: 规则变化直接更新Skill页，下次AI重新读取。
A6: 红色：红色标签工作表是公式及报表表，只能查看，禁止手工修改。 | B6: Red: Red-tab sheets are formula and report sheets. View only; do not edit manually.
A7: 目的 使用“主表 Stock_Transaction_Log”作为唯一的日常录入表。“Current_Stock_Detail 当前库存明细查询”自动生成，用于查询当前库存及混装托盘内容；“Warehouse_Layout 仓库可视化”和“Dashboard 简易报表”用于可视化查看。 | B7: Purpose Use “主表 Stock_Transaction_Log” as the only daily input table. “Current_Stock_Detail 当前库存明细查询” is generated automatically for current-stock and mixed-pallet queries. “Warehouse_Layout 仓库可视化” and “Dashboard 简易报表” provide visual views.
A8: 初次使用 1）确认“Location_Master库位维护”；2）确认“Product_Stock_Master产品维护”；3）在“主表 Stock_Transaction_Log”录入期初库存；4）检查当前库存明细、仓库可视化和简易报表。 | B8: Initial setup 1) Confirm “Location_Master库位维护”. 2) Confirm “Product_Stock_Master产品维护”. 3) Enter opening stock in “主表 Stock_Transaction_Log”. 4) Check the current-stock detail, warehouse visualization and dashboard.
A9: 产品分类 只有以下9个机型属于产品（Product）：EQ4800-S、EQ4800-M、CQ6-S、CQ6-M、KH10、KH8、H3-10.0-SMART、H3-15.0-SMART、CQ7-S。其余全部属于物料（Material），包括遮线罩等配件。 | B9: Product classification Only these nine models are classified as Product: EQ4800-S, EQ4800-M, CQ6-S, CQ6-M, KH10, KH8, H3-10.0-SMART, H3-15.0-SMART and CQ7-S. Everything else is Material, including cable covers and other accessories.
A10: 序列号规则 只有产品出库和产品退回维修需要序列号（SN）。期初库存、普通物料移动和混装物料托盘不需要序列号。 | B10: Serial-number rule Only Product Outbound and Product Return_to_Repair require an SN. Opening stock, normal material movements and mixed-material pallets do not require an SN.
A11: 混装托盘 使用 MIX-001 等容器编号（Container_Code），每个料号录入一行。仓库可视化只显示混装汇总；在当前库存明细中按容器编号筛选，可查看托盘内的具体内容。 | B11: Mixed pallet Use a Container_Code such as MIX-001 and enter one row per SKU. The warehouse visualization shows only the mixed summary. Filter the current-stock detail by Container_Code to view the pallet contents.
A12: 库存状态 在库：当前数量大于0；已出库：当前数量等于0；负库存：当前数量小于0。“重复”不作为库存状态。 | B12: Stock status In Stock: Current_Qty > 0. Out: Current_Qty = 0. Negative: Current_Qty < 0. Duplicate is not used as a stock status.
A13: 已备货 “已备货”只是备货记录，不影响库存。客户提货后，将操作改为“出库”，或另外录入一条出库记录。 | B13: Prepared Prepared is a preparation record only and does not affect stock. When the customer collects the goods, change the Action to Outbound or enter a separate Outbound row.
A14: 出库 出库会扣减来源库位（From_Location_Code）的库存。产品出库必须填写序列号。 | B14: Outbound Outbound reduces stock at the From_Location_Code. Product outbound requires an SN.
A15: 维修回退 维修回退会增加目标库位（To_Location_Code）的维修库存。产品退回维修必须填写序列号。 | B15: Return to repair Return_to_Repair increases repair stock at the To_Location_Code. Product return-to-repair requires an SN.
A16: 流程 ERP出货单/取货请求 → 已备货 → 客户提货时出库 → 旧机退回维修 → 在简易报表中检查待处理事项和异常。 | B16: Process ERP SH / pickup request → Prepared → Outbound when collected → old unit Return_to_Repair → review pending items and exceptions on the dashboard.
A17: 图表颜色 绿色表示可编辑区域；红色表示公式区域，不可编辑；黄色表示维护区域。 | B17: Chart colors Green indicates editable areas. Red indicates formula areas and must not be edited. Yellow indicates maintenance areas.
... A96: 报表辅助列 主表W:Z继续作为报表辅助列：唯一SH/动作标记、旧机未返标记、报表整机标记及报表分组。必须保留其公式与依赖关系。 | B96: Reporting-helper rule Main-table W:Z remain reporting helpers: unique SH/action flag, outstanding-return flag, report-machine flag and report group. Preserve their formulas and dependencies.

Sheet 主表 Stock_Transaction_Log
A1: Date / 日期 | B1: Outbound_Date / 实际出库日 | C1: Action / 动作 | D1: SH_No / ERP SH单号 | E1: Pickup_Code / 取货码 | F1: Container_Code / 容器码 | G1: SKU / 料号 | H1: Model / 机型 | I1: Item_Type / 物品类型 | J1: SN / 机器唯一码 | K1: Qty / 数量 | L1: From_Location_Code / 来源库位 | M1: To_Location_Code / 目标库位 | N1: ERP仓库选择 | O1: Validation_Check / 检查 | P1: Stock_Condition / 库存属性（必填） | Q1: 公式辅助位勿动 | R1: 公式辅助位勿动 | S1: 公式辅助位勿动 | T1: 公式辅助位勿动 | U1: 公式辅助位勿动 | V1: Remark / 备注 | W1: Condition_Check / 属性校验 | X1: Unique_SH_Action_Flag / 单据去重标记 | Y1: Outstanding_Return_Flag / 旧机未返标记 | Z1: Report_Machine_Flag / 报表整机标记 | AA1: Report_Group / 报表类别 | AB1: Move_Source_Key / 移库来源Key | AC1: Move_Source_Qty / 移库来源数量
A2: 2026-07-15 | C2: Opening | G2: 97-414-00027-00 | H2: =IF(G2="","",IFERROR(VLOOKUP(G2,'Product_Stock_Master产品维护'!$A$2:$E992,2,FALSE()),"SKU not found")) -> EQ4800-side-cover | I2: =IF(G2="","",IFERROR(VLOOKUP(G2,'Product_Stock_Master产品维护'!$A$2:$E992,3,FALSE()),"Item type not found")) -> Material | K2: 288 | M2: R1-2-1-L | O2: =IF(C2="","",IF(AND(G2="",NOT(AND(C2="Adjustment_In",P2="Material / 物料"))),"Missing SKU / 缺料号",IF(K2="","Missing Qty / 缺数量",IF(AND(I2="Product",OR(C2="Outbound",C2="Return_to_Repair"),J2=""),"Missing SN for product outbound/return / 成品出库或维修回退缺SN",IF(C2="Move",IF(OR(L2="",M2=""),"Missing Move location / 移库缺来源或目标库位","OK"),IF(OR(C2="Opening",C2="Inbound",C2="Return_to_Repair",C2="Adjustment_In"),IF(M2="","Missing To Location / 缺目标库位","OK"),IF(OR(C2="Outbound",C2="Adjustment_Out",C2="Prepared"),IF(L2="","Missing From Location / 缺来源库位","OK"),"OK"))))))) -> OK | P2: Material / 物料 | Q2: =IF(C2="","",IF(OR(C2="Opening",C2="Inbound",C2="Return_to_Repair",C2="Adjustment_In"),M2,IF(OR(C2="Outbound",C2="Move",C2="Adjustment_Out",C2="Prepared"),L2,""))) -> R1-2-1-L | R2: =IF(C2="","",IF(C2="Return_to_Repair",J2,"")) | S2: =IF(C2="","",IF(C2="Prepared",0,IF(OR(C2="Opening",C2="Inbound",C2="Return_to_Repair",C2="Adjustment_In"),K2,IF(OR(C2="Outbound",C2="Adjustment_Out",C2="Move"),-K2,0)))) -> 288 | T2: =IF(Q2="","",Q2&"|"&F2&"|"&G2&"|"&R2&"|"&P2) -> R1-2-1-L||97-414-00027-00||Material / 物料 | U2: Formula helper / 公式辅助 | V2: Opening balance imported from SYD_Basic_Stock_Capture_Template (1).xlsx | W2: =IF(A2="","",IF(AND(Z2="Yes",P2=""),"Missing stock condition / 缺库存属性",IF(AND(P2="New / 新机",C2="Return_to_Repair"),"New/repair conflict / 新机维修冲突","OK"))) -> OK | X2: =IF(OR(C2="",D2=""),0,IF(COUNTIFS($C$2:C2,C2,$D$2:D2,D2)=1,1,0)) -> 0 | Y2: =IF(AND(C2="Outbound",D2<>"",COUNTIFS($C$2:C2,"Outbound",$D$2:D2,D2)=1,COUNTIFS($C$2:$C992,"Return_to_Repair",$D$2:$D992,D2)=0),1,0) -> 0 | Z2: =IF(G2="","",IFERROR(VLOOKUP(G2,'Product_Stock_Master产品维护'!$A$2:$L992,11,FALSE),"No")) -> No | AA2: =IF(G2="","",IFERROR(VLOOKUP(G2,'Product_Stock_Master产品维护'!$A$2:$L992,12,FALSE),""))
A3: 2026-07-15 | C3: Opening | G3: 97-414-00027-00 | H3: =IF(G3="","",IFERROR(VLOOKUP(G3,'Product_Stock_Master产品维护'!$A$2:$E992,2,FALSE()),"SKU not found")) -> EQ4800-side-cover | I3: =IF(G3="","",IFERROR(VLOOKUP(G3,'Product_Stock_Master产品维护'!$A$2:$E992,3,FALSE()),"Item type not found")) -> Material | K3: 286 | M3: R1-2-1-M | O3: =IF(C3="","",IF(AND(G3="",NOT(AND(C3="Adjustment_In",P3="Material / 物料"))),"Missing SKU / 缺料号",IF(K3="","Missing Qty / 缺数量",IF(AND(I3="Product",OR(C3="Outbound",C3="Return_to_Repair"),J3=""),"Missing SN for product outbound/return / 成品出库或维修回退缺SN",IF(C3="Move",IF(OR(L3="",M3=""),"Missing Move location / 移库缺来源或目标库位","OK"),IF(OR(C3="Opening",C3="Inbound",C3="Return_to_Repair",C3="Adjustment_In"),IF(M3="","Missing To Location / 缺目标库位","OK"),IF(OR(C3="Outbound",C3="Adjustment_Out",C3="Prepared"),IF(L3="","Missing From Location / 缺来源库位","OK"),"OK"))))))) -> OK | P3: Material / 物料 | Q3: =IF(C3="","",IF(OR(C3="Opening",C3="Inbound",C3="Return_to_Repair",C3="Adjustment_In"),M3,IF(OR(C3="Outbound",C3="Move",C3="Adjustment_Out",C3="Prepared"),L3,""))) -> R1-2-1-M | R3: =IF(C3="","",IF(C3="Return_to_Repair",J3,"")) | S3: =IF(C3="","",IF(C3="Prepared",0,IF(OR(C3="Opening",C3="Inbound",C3="Return_to_Repair",C3="Adjustment_In"),K3,IF(OR(C3="Outbound",C3="Adjustment_Out",C3="Move"),-K3,0)))) -> 286 | T3: =IF(Q3="","",Q3&"|"&F3&"|"&G3&"|"&R3&"|"&P3) -> R1-2-1-M||97-414-00027-00||Material / 物料 | U3: Formula helper / 公式辅助 | V3: Opening balance imported from SYD_Basic_Stock_Capture_Template (1).xlsx | W3: =IF(A3="","",IF(AND(Z3="Yes",P3=""),"Missing stock condition / 缺库存属性",IF(AND(P3="New / 新机",C3="Return_to_Repair"),"New/repair conflict / 新机维修冲突","OK"))) -> OK | X3: =IF(OR(C3="",D3=""),0,IF(COUNTIFS($C$2:C3,C3,$D$2:D3,D3)=1,1,0)) -> 0 | Y3: =IF(AND(C3="Outbound",D3<>"",COUNTIFS($C$2:C3,"Outbound",$D$2:D3,D3)=1,COUNTIFS($C$2:$C993,"Return_to_Repair",$D$2:$D993,D3)=0),1,0) -> 0 | Z3: =IF(G3="","",IFERROR(VLOOKUP(G3,'Product_Stock_Master产品维护'!$A$2:$L992,11,FALSE),"No")) -> No | AA3: =IF(G3="","",IFERROR(VLOOKUP(G3,'Product_Stock_Master产品维护'!$A$2:$L992,12,FALSE),""))
A4: 2026-07-15 | C4: Opening | G4: 41-406-00002-00 | H4: =IF(G4="","",IFERROR(VLOOKUP(G4,'Product_Stock_Master产品维护'!$A$2:$E992,2,FALSE()),"SKU not found")) -> H3 Smart遮线罩 | I4: =IF(G4="","",IFERROR(VLOOKUP(G4,'Product_Stock_Master产品维护'!$A$2:$E992,3,FALSE()),"Item type not found")) -> Material | K4: 42 | M4: R1-2-1-R | O4: =IF(C4="","",IF(AND(G4="",NOT(AND(C4="Adjustment_In",P4="Material / 物料"))),"Missing SKU / 缺料号",IF(K4="","Missing Qty / 缺数量",IF(AND(I4="Product",OR(C4="Outbound",C4="Return_to_Repair"),J4=""),"Missing SN for product outbound/return / 成品出库或维修回退缺SN",IF(C4="Move",IF(OR(L4="",M4=""),"Missing Move location / 移库缺来源或目标库位","OK"),IF(OR(C4="Opening",C4="Inbound",C4="Return_to_Repair",C4="Adjustment_In"),IF(M4="","Missing To Location / 缺目标库位","OK"),IF(OR(C4="Outbound",C4="Adjustment_Out",C4="Prepared"),IF(L4="","Missing From Location / 缺来源库位","OK"),"OK"))))))) -> OK | P4: Material / 物料 | Q4: =IF(C4="","",IF(OR(C4="Opening",C4="Inbound",C4="Return_to_Repair",C4="Adjustment_In"),M4,IF(OR(C4="Outbound",C4="Move",C4="Adjustment_Out",C4="Prepared"),L4,""))) -> R1-2-1-R | R4: =IF(C4="","",IF(C4="Return_to_Repair",J4,"")) | S4: =IF(C4="","",IF(C4="Prepared",0,IF(OR(C4="Opening",C4="Inbound",C4="Return_to_Repair",C4="Adjustment_In"),K4,IF(OR(C4="Outbound",C4="Adjustment_Out",C4="Move"),-K4,0)))) -> 42 | T4: =IF(Q4="","",Q4&"|"&F4&"|"&G4&"|"&R4&"|"&P4) -> R1-2-1-R||41-406-00002-00||Material / 物料 | U4: Formula helper / 公式辅助 | V4: Opening balance imported from SYD_Basic_Stock_Capture_Template (1).xlsx | W4: =IF(A4="","",IF(AND(Z4="Yes",P4=""),"Missing stock condition / 缺库存属性",IF(AND(P4="New / 新机",C4="Return_to_Repair"),"New/repair conflict / 新机维修冲突","OK"))) -> OK | X4: =IF(OR(C4="",D4=""),0,IF(COUNTIFS($C$2:C4,C4,$D$2:D4,D4)=1,1,0)) -> 0 | Y4: =IF(AND(C4="Outbound",D4<>"",COUNTIFS($C$2:C4,"Outbound",$D$2:D4,D4)=1,COUNTIFS($C$2:$C994,"Return_to_Repair",$D$2:$D994,D4)=0),1,0) -> 0 | Z4: =IF(G4="","",IFERROR(VLOOKUP(G4,'Product_Stock_Master产品维护'!$A$2:$L992,11,FALSE),"No")) -> No | AA4: =IF(G4="","",IFERROR(VLOOKUP(G4,'Product_Stock_Master产品维护'!$A$2:$L992,12,FALSE),""))
A5: 2026-07-15 | C5: Opening | G5: 20-051-00080-00 | H5: =IF(G5="","",IFERROR(VLOOKUP(G5,'Product_Stock_Master产品维护'!$A$2:$E992,2,FALSE()),"SKU not found")) -> 线束半成品 功率线 62930 IEC 131 1x16.0 mm² 红/黑 DC1500V 90℃ VW-1 CQ6-安费诺-正负极外部动力线-光伏线5米PV | I5: =IF(G5="","",IFERROR(VLOOKUP(G5,'Product_Stock_Master产品维护'!$A$2:$E992,3,FALSE()),"Item type not found")) -> Material | K5: 130 | M5: R1-3-1-L | O5: =IF(C5="","",IF(AND(G5="",NOT(AND(C5="Adjustment_In",P5="Material / 物料"))),"Missing SKU / 缺料号",IF(K5="","Missing Qty / 缺数量",IF(AND(I5="Product",OR(C5="Outbound",C5="Return_to_Repair"),J5=""),"Missing SN for product outbound/return / 成品出库或维修回退缺SN",IF(C5="Move",IF(OR(L5="",M5=""),"Missing Move location / 移库缺来源或目标库位","OK"),IF(OR(C5="Opening",C5="Inbound",C5="Return_to_Repair",C5="Adjustment_In"),IF(M5="","Missing To Location / 缺目标库位","OK"),IF(OR(C5="Outbound",C5="Adjustment_Out",C5="Prepared"),IF(L5="","Missing From Location / 缺来源库位","OK"),"OK"))))))) -> OK | P5: Material / 物料 | Q5: =IF(C5="","",IF(OR(C5="Opening",C5="Inbound",C5="Return_to_Repair",C5="Adjustment_In"),M5,IF(OR(C5="Outbound",C5="Move",C5="Adjustment_Out",C5="Prepared"),L5,""))) -> R1-3-1-L | R5: =IF(C5="","",IF(C5="Return_to_Repair",J5,"")) | S5: =IF(C5="","",IF(C5="Prepared",0,IF(OR(C5="Opening",C5="Inbound",C5="Return_to_Repair",C5="Adjustment_In"),K5,IF(OR(C5="Outbound",C5="Adjustment_Out",C5="Move"),-K5,0)))) -> 130 | T5: =IF(Q5="","",Q5&"|"&F5&"|"&G5&"|"&R5&"|"&P5) -> R1-3-1-L||20-051-00080-00||Material / 物料 | U5: Formula helper / 公式辅助 | V5: Opening balance imported from SYD_Basic_Stock_Capture_Template (1).xlsx | W5: =IF(A5="","",IF(AND(Z5="Yes",P5=""),"Missing stock condition / 缺库存属性",IF(AND(P5="New / 新机",C5="Return_to_Repair"),"New/repair conflict / 新机维修冲突","OK"))) -> OK | X5: =IF(OR(C5="",D5=""),0,IF(COUNTIFS($C$2:C5,C5,$D$2:D5,D5)=1,1,0)) -> 0 | Y5: =IF(AND(C5="Outbound",D5<>"",COUNTIFS($C$2:C5,"Outbound",$D$2:D5,D5)=1,COUNTIFS($C$2:$C995,"Return_to_Repair",$D$2:$D995,D5)=0),1,0) -> 0 | Z5: =IF(G5="","",IFERROR(VLOOKUP(G5,'Product_Stock_Master产品维护'!$A$2:$L992,11,FALSE),"No")) -> No | AA5: =IF(G5="","",IFERROR(VLOOKUP(G5,'Product_Stock_Master产品维护'!$A$2:$L992,12,FALSE),""))
A6: 2026-07-15 | C6: Opening | G6: 41-406-00002-00 | H6: =IF(G6="","",IFERROR(VLOOKUP(G6,'Product_Stock_Master产品维护'!$A$2:$E992,2,FALSE()),"SKU not found")) -> H3 Smart遮线罩 | I6: =IF(G6="","",IFERROR(VLOOKUP(G6,'Product_Stock_Master产品维护'!$A$2:$E992,3,FALSE()),"Item type not found")) -> Material | K6: 42 | M6: R1-3-1-M | O6: =IF(C6="","",IF(AND(G6="",NOT(AND(C6="Adjustment_In",P6="Material / 物料"))),"Missing SKU / 缺料号",IF(K6="","Missing Qty / 缺数量",IF(AND(I6="Product",OR(C6="Outbound",C6="Return_to_Repair"),J6=""),"Missing SN for product outbound/return / 成品出库或维修回退缺SN",IF(C6="Move",IF(OR(L6="",M6=""),"Missing Move location / 移库缺来源或目标库位","OK"),IF(OR(C6="Opening",C6="Inbound",C6="Return_to_Repair",C6="Adjustment_In"),IF(M6="","Missing To Location / 缺目标库位","OK"),IF(OR(C6="Outbound",C6="Adjustment_Out",C6="Prepared"),IF(L6="","Missing From Location / 缺来源库位","OK"),"OK"))))))) -> OK | P6: Material / 物料 | Q6: =IF(C6="","",IF(OR(C6="Opening",C6="Inbound",C6="Return_to_Repair",C6="Adjustment_In"),M6,IF(OR(C6="Outbound",C6="Move",C6="Adjustment_Out",C6="Prepared"),L6,""))) -> R1-3-1-M | R6: =IF(C6="","",IF(C6="Return_to_Repair",J6,"")) | S6: =IF(C6="","",IF(C6="Prepared",0,IF(OR(C6="Opening",C6="Inbound",C6="Return_to_Repair",C6="Adjustment_In"),K6,IF(OR(C6="Outbound",C6="Adjustment_Out",C6="Move"),-K6,0)))) -> 42 | T6: =IF(Q6="","",Q6&"|"&F6&"|"&G6&"|"&R6&"|"&P6) -> R1-3-1-M||41-406-00002-00||Material / 物料 | U6: Formula helper / 公式辅助 | V6: Opening balance imported from SYD_Basic_Stock_Capture_Template (1).xlsx | W6: =IF(A6="","",IF(AND(Z6="Yes",P6=""),"Missing stock condition / 缺库存属性",IF(AND(P6="New / 新机",C6="Return_to_Repair"),"New/repair conflict / 新机维修冲突","OK"))) -> OK | X6: =IF(OR(C6="",D6=""),0,IF(COUNTIFS($C$2:C6,C6,$D$2:D6,D6)=1,1,0)) -> 0 | Y6: =IF(AND(C6="Outbound",D6<>"",COUNTIFS($C$2:C6,"Outbound",$D$2:D6,D6)=1,COUNTIFS($C$2:$C996,"Return_to_Repair",$D$2:$D996,D6)=0),1,0) -> 0 | Z6: =IF(G6="","",IFERROR(VLOOKUP(G6,'Product_Stock_Master产品维护'!$A$2:$L992,11,FALSE),"No")) -> No | AA6: =IF(G6="","",IFERROR(VLOOKUP(G6,'Product_Stock_Master产品维护'!$A$2:$L992,12,FALSE),""))
A7: 2026-07-15 | C7: Opening | G7: 41-406-00002-00 | H7: =IF(G7="","",IFERROR(VLOOKUP(G7,'Product_Stock_Master产品维护'!$A$2:$E992,2,FALSE()),"SKU not found")) -> H3 Smart遮线罩 | I7: =IF(G7="","",IFERROR(VLOOKUP(G7,'Product_Stock_Master产品维护'!$A$2:$E992,3,FALSE()),"Item type not found")) -> Material | K7: 42 | M7: R1-3-1-R | O7: =IF(C7="","",IF(AND(G7="",NOT(AND(C7="Adjustment_In",P7="Material / 物料"))),"Missing SKU / 缺料号",IF(K7="","Missing Qty / 缺数量",IF(AND(I7="Product",OR(C7="Outbound",C7="Return_to_Repair"),J7=""),"Missing SN for product outbound/return / 成品出库或维修回退缺SN",IF(C7="Move",IF(OR(L7="",M7=""),"Missing Move location / 移库缺来源或目标库位","OK"),IF(OR(C7="Opening",C7="Inbound",C7="Return_to_Repair",C7="Adjustment_In"),IF(M7="","Missing To Location / 缺目标库位","OK"),IF(OR(C7="Outbound",C7="Adjustment_Out",C7="Prepared"),IF(L7="","Missing From Location / 缺来源库位","OK"),"OK"))))))) -> OK | P7: Material / 物料 | Q7: =IF(C7="","",IF(OR(C7="Opening",C7="Inbound",C7="Return_to_Repair",C7="Adjustment_In"),M7,IF(OR(C7="Outbound",C7="Move",C7="Adjustment_Out",C7="Prepared"),L7,""))) -> R1-3-1-R | R7: =IF(C7="","",IF(C7="Return_to_Repair",J7,"")) | S7: =IF(C7="","",IF(C7="Prepared",0,IF(OR(C7="Opening",C7="Inbound",C7="Return_to_Repair",C7="Adjustment_In"),K7,IF(OR(C7="Outbound",C7="Adjustment_Out",C7="Move"),-K7,0)))) -> 42 | T7: =IF(Q7="","",Q7&"|"&F7&"|"&G7&"|"&R7&"|"&P7) -> R1-3-1-R||41-406-00002-00||Material / 物料 | U7: Formula helper / 公式辅助 | V7: Opening balance imported from SYD_Basic_Stock_Capture_Template (1).xlsx | W7: =IF(A7="","",IF(AND(Z7="Yes",P7=""),"Missing stock condition / 缺库存属性",IF(AND(P7="New / 新机",C7="Return_to_Repair"),"New/repair conflict / 新机维修冲突","OK"))) -> OK | X7: =IF(OR(C7="",D7=""),0,IF(COUNTIFS($C$2:C7,C7,$D$2:D7,D7)=1,1,0)) -> 0 | Y7: =IF(AND(C7="Outbound",D7<>"",COUNTIFS($C$2:C7,"Outbound",$D$2:D7,D7)=1,COUNTIFS($C$2:$C997,"Return_to_Repair",$D$2:$D997,D7)=0),1,0) -> 0 | Z7: =IF(G7="","",IFERROR(VLOOKUP(G7,'Product_Stock_Master产品维护'!$A$2:$L992,11,FALSE),"No")) -> No | AA7: =IF(G7="","",IFERROR(VLOOKUP(G7,'Product_Stock_Master产品维护'!$A$2:$L992,12,FALSE),""))
A8: 2026-07-15 | C8: Opening | G8: 97-406-00017-00 | H8: =IF(G8="","",IFERROR(VLOOKUP(G8,'Product_Stock_Master产品维护'!$A$2:$E992,2,FALSE()),"SKU not found")) -> KH遮线罩 | I8: =IF(G8="","",IFERROR(VLOOKUP(G8,'Product_Stock_Master产品维护'!$A$2:$E992,3,FALSE()),"Item type not found")) -> Material | K8: 96 | M8: R1-4-1-L | O8: =IF(C8="","",IF(AND(G8="",NOT(AND(C8="Adjustment_In",P8="Material / 物料"))),"Missing SKU / 缺料号",IF(K8="","Missing Qty / 缺数量",IF(AND(I8="Product",OR(C8="Outbound",C8="Return_to_Repair"),J8=""),"Missing SN for product outbound/return / 成品出库或维修回退缺SN",IF(C8="Move",IF(OR(L8="",M8=""),"Missing Move location / 移库缺来源或目标库位","OK"),IF(OR(C8="Opening",C8="Inbound",C8="Return_to_Repair",C8="Adjustment_In"),IF(M8="","Missing To Location / 缺目标库位","OK"),IF(OR(C8="Outbound",C8="Adjustment_Out",C8="Prepared"),IF(L8="","Missing From Location / 缺来源库位","OK"),"OK"))))))) -> OK | P8: Material / 物料 | Q8: =IF(C8="","",IF(OR(C8="Opening",C8="Inbound",C8="Return_to_Repair",C8="Adjustment_In"),M8,IF(OR(C8="Outbound",C8="Move",C8="Adjustment_Out",C8="Prepared"),L8,""))) -> R1-4-1-L | R8: =IF(C8="","",IF(C8="Return_to_Repair",J8,"")) | S8: =IF(C8="","",IF(C8="Prepared",0,IF(OR(C8="Opening",C8="Inbound",C8="Return_to_Repair",C8="Adjustment_In"),K8,IF(OR(C8="Outbound",C8="Adjustment_Out",C8="Move"),-K8,0)))) -> 96 | T8: =IF(Q8="","",Q8&"|"&F8&"|"&G8&"|"&R8&"|"&P8) -> R1-4-1-L||97-406-00017-00||Material / 物料 | U8: Formula helper / 公式辅助 | V8: Opening balance imported from SYD_Basic_Stock_Capture_Template (1).xlsx | W8: =IF(A8="","",IF(AND(Z8="Yes",P8=""),"Missing stock condition / 缺库存属性",IF(AND(P8="New / 新机",C8="Return_to_Repair"),"New/repair conflict / 新机维修冲突","OK"))) -> OK | X8: =IF(OR(C8="",D8=""),0,IF(COUNTIFS($C$2:C8,C8,$D$2:D8,D8)=1,1,0)) -> 0 | Y8: =IF(AND(C8="Outbound",D8<>"",COUNTIFS($C$2:C8,"Outbound",$D$2:D8,D8)=1,COUNTIFS($C$2:$C998,"Return_to_Repair",$D$2:$D998,D8)=0),1,0) -> 0 | Z8: =IF(G8="","",IFERROR(VLOOKUP(G8,'Product_Stock_Master产品维护'!$A$2:$L992,11,FALSE),"No")) -> No | AA8: =IF(G8="","",IFERROR(VLOOKUP(G8,'Product_Stock_Master产品维护'!$A$2:$L992,12,FALSE),""))
A9: 2026-07-15 | C9: Opening | G9: 10-120-00471-00 | H9: =IF(G9="","",IFERROR(VLOOKUP(G9,'Product_Stock_Master产品维护'!$A$2:$E992,2,FALSE()),"SKU not found")) -> 保温棉 橡胶泡棉 -90° -180° V-0 黑色 1主8从 上保温棉+下保温棉+四周保温棉(4+5) 带纸箱 | I9: =IF(G9="","",IFERROR(VLOOKUP(G9,'Product_Stock_Master产品维护'!$A$2:$E992,3,FALSE()),"Item type not found")) -> Material | K9: 19 | M9: R1-4-1-R | O9: =IF(C9="","",IF(AND(G9="",NOT(AND(C9="Adjustment_In",P9="Material / 物料"))),"Missing SKU / 缺料号",IF(K9="","Missing Qty / 缺数量",IF(AND(I9="Product",OR(C9="Outbound",C9="Return_to_Repair"),J9=""),"Missing SN for product outbound/return / 成品出库或维修回退缺SN",IF(C9="Move",IF(OR(L9="",M9=""),"Missing Move location / 移库缺来源或目标库位","OK"),IF(OR(C9="Opening",C9="Inbound",C9="Return_to_Repair",C9="Adjustment_In"),IF(M9="","Missing To Location / 缺目标库位","OK"),IF(OR(C9="Outbound",C9="Adjustment_Out",C9="Prepared"),IF(L9="","Missing From Location / 缺来源库位","OK"),"OK"))))))) -> OK | P9: Material / 物料 | Q9: =IF(C9="","",IF(OR(C9="Opening",C9="Inbound",C9="Return_to_Repair",C9="Adjustment_In"),M9,IF(OR(C9="Outbound",C9="Move",C9="Adjustment_Out",C9="Prepared"),L9,""))) -> R1-4-1-R | R9: =IF(C9="","",IF(C9="Return_to_Repair",J9,"")) | S9: =IF(C9="","",IF(C9="Prepared",0,IF(OR(C9="Opening",C9="Inbound",C9="Return_to_Repair",C9="Adjustment_In"),K9,IF(OR(C9="Outbound",C9="Adjustment_Out",C9="Move"),-K9,0)))) -> 19 | T9: =IF(Q9="","",Q9&"|"&F9&"|"&G9&"|"&R9&"|"&P9) -> R1-4-1-R||10-120-00471-00||Material / 物料 | U9: Formula helper / 公式辅助 | V9: Opening balance imported from SYD_Basic_Stock_Capture_Template (1).xlsx | W9: =IF(A9="","",IF(AND(Z9="Yes",P9=""),"Missing stock condition / 缺库存属性",IF(AND(P9="New / 新机",C9="Return_to_Repair"),"New/repair conflict / 新机维修冲突","OK"))) -> OK | X9: =IF(OR(C9="",D9=""),0,IF(COUNTIFS($C$2:C9,C9,$D$2:D9,D9)=1,1,0)) -> 0 | Y9: =IF(AND(C9="Outbound",D9<>"",COUNTIFS($C$2:C9,"Outbound",$D$2:D9,D9)=1,COUNTIFS($C$2:$C999,"Return_to_Repair",$D$2:$D999,D9)=0),1,0) -> 0 | Z9: =IF(G9="","",IFERROR(VLOOKUP(G9,'Product_Stock_Master产品维护'!$A$2:$L992,11,FALSE),"No")) | AA9: =IF(G9="","",IFERROR(VLOOKUP(G9,'Product_Stock_Master产品维护'!$A$2:$L992,12,FALSE),""))
A10: 2026-07-15 | C10: Opening | G10: 41-406-00002-00 | H10: =IF(G10="","",IFERROR(VLOOKUP(G10,'Product_Stock_Master产品维护'!$A$2:$E992,2,FALSE()),"SKU not found")) -> H3 Smart遮线罩 | I10: =IF(G10="","",IFERROR(VLOOKUP(G10,'Product_Stock_Master产品维护'!$A$2:$E992,3,FALSE()),"Item type not found")) -> Material | K10: 42 | M10: R1-2-2-L | O10: =IF(C10="","",IF(AND(G10="",NOT(AND(C10="Adjustment_In",P10="Material / 物料"))),"Missing SKU / 缺料号",IF(K10="","Missing Qty / 缺数量",IF(AND(I10="Product",OR(C10="Outbound",C10="Return_to_Repair"),J10=""),"Missing SN for product outbound/return / 成品出库或维修回退缺SN",IF(C10="Move",IF(OR(L10="",M10=""),"Missing Move location / 移库缺来源或目标库位","OK"),IF(OR(C10="Opening",C10="Inbound",C10="Return_to_Repair",C10="Adjustment_In"),IF(M10="","Missing To Location / 缺目标库位","OK"),IF(OR(C10="Outbound",C10="Adjustment_Out",C10="Prepared"),IF(L10="","Missing From Location / 缺来源库位","OK"),"OK"))))))) -> OK | P10: Material / 物料 | Q10: =IF(C10="","",IF(OR(C10="Opening",C10="Inbound",C10="Return_to_Repair",C10="Adjustment_In"),M10,IF(OR(C10="Outbound",C10="Move",C10="Adjustment_Out",C10="Prepared"),L10,""))) -> R1-2-2-L | R10: =IF(C10="","",IF(C10="Return_to_Repair",J10,"")) | S10: =IF(C10="","",IF(C10="Prepared",0,IF(OR(C10="Opening",C10="Inbound",C10="Return_to_Repair",C10="Adjustment_In"),K10,IF(OR(C10="Outbound",C10="Adjustment_Out",C10="Move"),-K10,0)))) -> 42 | T10: =IF(Q10="","",Q10&"|"&F10&"|"&G10&"|"&R10&"|"&P10) -> R1-2-2-L||41-406-00002-00||Material / 物料 | U10: Formula helper / 公式辅助 | V10: Opening balance imported from SYD_Basic_Stock_Capture_Template (1).xlsx | W10: =IF(A10="","",IF(AND(Z10="Yes",P10=""),"Missing stock condition / 缺库存属性",IF(AND(P10="New / 新机",C10="Return_to_Repair"),"New/repair conflict / 新机维修冲突","OK"))) -> OK | X10: =IF(OR(C10="",D10=""),0,IF(COUNTIFS($C$2:C10,C10,$D$2:D10,D10)=1,1,0)) -> 0 | Y10: =IF(AND(C10="Outbound",D10<>"",COUNTIFS($C$2:C10,"Outbound",$D$2:D10,D10)=1,COUNTIFS($C$2:$C1000,"Return_to_Repair",$D$2:$D1000,D10)=0),1,0) -> 0 | Z10: =IF(G10="","",IFERROR(VLOOKUP(G10,'Product_Stock_Master产品维护'!$A$2:$L992,11,FALSE),"No")) -> No | AA10: =IF(G10="","",IFERROR(VLOOKUP(G10,'Product_Stock_Master产品维护'!$A$2:$L992,12,FALSE),""))
A11: 2026-07-15 | C11: Opening | G11: 41-406-00002-00 | H11: =IF(G11="","",IFERROR(VLOOKUP(G11,'Product_Stock_Master产品维护'!$A$2:$E992,2,FALSE()),"SKU not found")) -> H3 Smart遮线罩 | I11: =IF(G11="","",IFERROR(VLOOKUP(G11,'Product_Stock_Master产品维护'!$A$2:$E992,3,FALSE()),"Item type not found")) -> Material | K11: 42 | M11: R1-2-2-M | O11: =IF(C11="","",IF(AND(G11="",NOT(AND(C11="Adjustment_In",P11="Material / 物料"))),"Missing SKU / 缺料号",IF(K11="","Missing Qty / 缺数量",IF(AND(I11="Product",OR(C11="Outbound",C11="Return_to_Repair"),J11=""),"Missing SN for product outbound/return / 成品出库或维修回退缺SN",IF(C11="Move",IF(OR(L11="",M11=""),"Missing Move location / 移库缺来源或目标库位","OK"),IF(OR(C11="Opening",C11="Inbound",C11="Return_to_Repair",C11="Adjustment_In"),IF(M11="","Missing To Location / 缺目标库位","OK"),IF(OR(C11="Outbound",C11="Adjustment_Out",C11="Prepared"),IF(L11="","Missing From Location / 缺来源库位","OK"),"OK"))))))) -> OK | P11: Material / 物料 | Q11: =IF(C11="","",IF(OR(C11="Opening",C11="Inbound",C11="Return_to_Repair",C11="Adjustment_In"),M11,IF(OR(C11="Outbound",C11="Move",C11="Adjustment_Out",C11="Prepared"),L11,""))) -> R1-2-2-M | R11: =IF(C11="","",IF(C11="Return_to_Repair",J11,"")) | S11: =IF(C11="","",IF(C11="Prepared",0,IF(OR(C11="Opening",C11="Inbound",C11="Return_to_Repair",C11="Adjustment_In"),K11,IF(OR(C11="Outbound",C11="Adjustment_Out",C11="Move"),-K11,0)))) -> 42 | T11: =IF(Q11="","",Q11&"|"&F11&"|"&G11&"|"&R11&"|"&P11) -> R1-2-2-M||41-406-00002-00||Material / 物料 | U11: Formula helper / 公式辅助 | V11: Opening balance imported from SYD_Basic_Stock_Capture_Template (1).xlsx | W11: =IF(A11="","",IF(AND(Z11="Yes",P11=""),"Missing stock condition / 缺库存属性",IF(AND(P11="New / 新机",C11="Return_to_Repair"),"New/repair conflict / 新机维修冲突","OK"))) -> OK | X11: =IF(OR(C11="",D11=""),0,IF(COUNTIFS($C$2:C11,C11,$D$2:D11,D11)=1,1,0)) -> 0 | Y11: =IF(AND(C11="Outbound",D11<>"",COUNTIFS($C$2:C11,"Outbound",$D$2:D11,D11)=1,COUNTIFS($C$2:$C1001,"Return_to_Repair",$D$2:$D1001,D11)=0),1,0) -> 0 | Z11: =IF(G11="","",IFERROR(VLOOKUP(G11,'Product_Stock_Master产品维护'!$A$2:$L992,11,FALSE),"No")) -> No | AA11: =IF(G11="","",IFERROR(VLOOKUP(G11,'Product_Stock_Master产品维护'!$A$2:$L992,12,FALSE),""))
A12: 2026-07-15 | C12: Opening | G12: 41-406-00002-00 | H12: =IF(G12="","",IFERROR(VLOOKUP(G12,'Product_Stock_Master产品维护'!$A$2:$E992,2,FALSE()),"SKU not found")) -> H3 Smart遮线罩 | I12: =IF(G12="","",IFERROR(VLOOKUP(G12,'Product_Stock_Master产品维护'!$A$2:$E992,3,FALSE()),"Item type not found")) -> Material | K12: 42 | M12: R1-2-2-R | O12: =IF(C12="","",IF(AND(G12="",NOT(AND(C12="Adjustment_In",P12="Material / 物料"))),"Missing SKU / 缺料号",IF(K12="","Missing Qty / 缺数量",IF(AND(I12="Product",OR(C12="Outbound",C12="Return_to_Repair"),J12=""),"Missing SN for product outbound/return / 成品出库或维修回退缺SN",IF(C12="Move",IF(OR(L12="",M12=""),"Missing Move location / 移库缺来源或目标库位","OK"),IF(OR(C12="Opening",C12="Inbound",C12="Return_to_Repair",C12="Adjustment_In"),IF(M12="","Missing To Location / 缺目标库位","OK"),IF(OR(C12="Outbound",C12="Adjustment_Out",C12="Prepared"),IF(L12="","Missing From Location / 缺来源库位","OK"),"OK"))))))) -> OK | P12: Material / 物料 | Q12: =IF(C12="","",IF(OR(C12="Opening",C12="Inbound",C12="Return_to_Repair",C12="Adjustment_In"),M12,IF(OR(C12="Outbound",C12="Move",C12="Adjustment_Out",C12="Prepared"),L12,""))) -> R1-2-2-R | R12: =IF(C12="","",IF(C12="Return_to_Repair",J12,"")) | S12: =IF(C12="","",IF(C12="Prepared",0,IF(OR(C12="Opening",C12="Inbound",C12="Return_to_Repair",C12="Adjustment_In"),K12,IF(OR(C12="Outbound",C12="Adjustment_Out",C12="Move"),-K12,0)))) -> 42 | T12: =IF(Q12="","",Q12&"|"&F12&"|"&G12&"|"&R12&"|"&P12) -> R1-2-2-R||41-406-00002-00||Material / 物料 | U12: Formula helper / 公式辅助 | V12: Opening balance imported from SYD_Basic_Stock_Capture_Template (1).xlsx | W12: =IF(A12="","",IF(AND(Z12="Yes",P12=""),"Missing stock condition / 缺库存属性",IF(AND(P12="New / 新机",C12="Return_to_Repair"),"New/repair conflict / 新机维修冲突","OK"))) -> OK | X12: =IF(OR(C12="",D12=""),0,IF(COUNTIFS($C$2:C12,C12,$D$2:D12,D12)=1,1,0)) -> 0 | Y12: =IF(AND(C12="Outbound",D12<>"",COUNTIFS($C$2:C12,"Outbound",$D$2:D12,D12)=1,COUNTIFS($C$2:$C1002,"Return_to_Repair",$D$2:$D1002,D12)=0),1,0) -> 0 | Z12: =IF(G12="","",IFERROR(VLOOKUP(G12,'Product_Stock_Master产品维护'!$A$2:$L992,11,FALSE),"No")) -> No | AA12: =IF(G12="","",IFERROR(VLOOKUP(G12,'Product_Stock_Master产品维护'!$A$2:$L992,12,FALSE),""))
A13: 2026-07-15 | C13: Opening | G13: 41-406-00002-00 | H13: =IF(G13="","",IFERROR(VLOOKUP(G13,'Product_Stock_Master产品维护'!$A$2:$E992,2,FALSE()),"SKU not found")) -> H3 Smart遮线罩 | I13: =IF(G13="","",IFERROR(VLOOKUP(G13,'Product_Stock_Master产品维护'!$A$2:$E992,3,FALSE()),"Item type not found")) -> Material | K13: 42 | M13: R1-3-2-L | O13: =IF(C13="","",IF(AND(G13="",NOT(AND(C13="Adjustment_In",P13="Material / 物料"))),"Missing SKU / 缺料号",IF(K13="","Missing Qty / 缺数量",IF(AND(I13="Product",OR(C13="Outbound",C13="Return_to_Repair"),J13=""),"Missing SN for product outbound/return / 成品出库或维修回退缺SN",IF(C13="Move",IF(OR(L13="",M13=""),"Missing Move location / 移库缺来源或目标库位","OK"),IF(OR(C13="Opening",C13="Inbound",C13="Return_to_Repair",C13="Adjustment_In"),IF(M13="","Missing To Location / 缺目标库位","OK"),IF(OR(C13="Outbound",C13="Adjustment_Out",C13="Prepared"),IF(L13="","Missing From Location / 缺来源库位","OK"),"OK"))))))) -> OK | P13: Material / 物料 | Q13: =IF(C13="","",IF(OR(C13="Opening",C13="Inbound",C13="Return_to_Repair",C13="Adjustment_In"),M13,IF(OR(C13="Outbound",C13="Move",C13="Adjustment_Out",C13="Prepared"),L13,""))) -> R1-3-2-L | R13: =IF(C13="","",IF(C13="Return_to_Repair",J13,"")) | S13: =IF(C13="","",IF(C13="Prepared",0,IF(OR(C13="Opening",C13="Inbound",C13="Return_to_Repair",C13="Adjustment_In"),K13,IF(OR(C13="Outbound",C13="Adjustment_Out",C13="Move"),-K13,0)))) -> 42 | T13: =IF(Q13="","",Q13&"|"&F13&"|"&G13&"|"&R13&"|"&P13) -> R1-3-2-L||41-406-00002-00||Material / 物料 | U13: Formula helper / 公式辅助 | V13: Opening balance imported from SYD_Basic_Stock_Capture_Template (1).xlsx | W13: =IF(A13="","",IF(AND(Z13="Yes",P13=""),"Missing stock condition / 缺库存属性",IF(AND(P13="New / 新机",C13="Return_to_Repair"),"New/repair conflict / 新机维修冲突","OK"))) -> OK | X13: =IF(OR(C13="",D13=""),0,IF(COUNTIFS($C$2:C13,C13,$D$2:D13,D13)=1,1,0)) -> 0 | Y13: =IF(AND(C13="Outbound",D13<>"",COUNTIFS($C$2:C13,"Outbound",$D$2:D13,D13)=1,COUNTIFS($C$2:$C1003,"Return_to_Repair",$D$2:$D1003,D13)=0),1,0) -> 0 | Z13: =IF(G13="","",IFERROR(VLOOKUP(G13,'Product_Stock_Master产品维护'!$A$2:$L992,11,FALSE),"No")) -> No | AA13: =IF(G13="","",IFERROR(VLOOKUP(G13,'Product_Stock_Master产品维护'!$A$2:$L992,12,FALSE),""))
A14: 2026-07-15 | C14: Opening | G14: 41-406-00002-00 | H14: =IF(G14="","",IFERROR(VLOOKUP(G14,'Product_Stock_Master产品维护'!$A$2:$E992,2,FALSE()),"SKU not found")) -> H3 Smart遮线罩 | I14: =IF(G14="","",IFERROR(VLOOKUP(G14,'Product_Stock_Master产品维护'!$A$2:$E992,3,FALSE()),"Item type not found")) -> Material | K14: 42 | M14: R1-3-2-M | O14: =IF(C14="","",IF(AND(G14="",NOT(AND(C14="Adjustment_In",P14="Material / 物料"))),"Missing SKU / 缺料号",IF(K14="","Missing Qty / 缺数量",IF(AND(I14="Product",OR(C14="Outbound",C14="Return_to_Repair"),J14=""),"Missing SN for product outbound/return / 成品出库或维修回退缺SN",IF(C14="Move",IF(OR(L14="",M14=""),"Missing Move location / 移库缺来源或目标库位","OK"),IF(OR(C14="Opening",C14="Inbound",C14="Return_to_Repair",C14="Adjustment_In"),IF(M14="","Missing To Location / 缺目标库位","OK"),IF(OR(C14="Outbound",C14="Adjustment_Out",C14="Prepared"),IF(L14="","Missing From Location / 缺来源库位","OK"),"OK"))))))) -> OK | P14: Material / 物料 | Q14: =IF(C14="","",IF(OR(C14="Opening",C14="Inbound",C14="Return_to_Repair",C14="Adjustment_In"),M14,IF(OR(C14="Outbound",C14="Move",C14="Adjustment_Out",C14="Prepared"),L14,""))) -> R1-3-2-M | R14: =IF(C14="","",IF(C14="Return_to_Repair",J14,"")) | S14: =IF(C14="","",IF(C14="Prepared",0,IF(OR(C14="Opening",C14="Inbound",C14="Return_to_Repair",C14="Adjustment_In"),K14,IF(OR(C14="Outbound",C14="Adjustment_Out",C14="Move"),-K14,0)))) -> 42 | T14: =IF(Q14="","",Q14&"|"&F14&"|"&G14&"|"&R14&"|"&P14) -> R1-3-2-M||41-406-00002-00||Material / 物料 | U14: Formula helper / 公式辅助 | V14: Opening balance imported from SYD_Basic_Stock_Capture_Template (1).xlsx | W14: =IF(A14="","",IF(AND(Z14="Yes",P14=""),"Missing stock condition / 缺库存属性",IF(AND(P14="New / 新机",C14="Return_to_Repair"),"New/repair conflict / 新机维修冲突","OK"))) -> OK | X14: =IF(OR(C14="",D14=""),0,IF(COUNTIFS($C$2:C14,C14,$D$2:D14,D14)=1,1,0)) -> 0 | Y14: =IF(AND(C14="Outbound",D14<>"",COUNTIFS($C$2:C14,"Outbound",$D$2:D14,D14)=1,COUNTIFS($C$2:$C1004,"Return_to_Repair",$D$2:$D1004,D14)=0),1,0) -> 0 | Z14: =IF(G14="","",IFERROR(VLOOKUP(G14,'Product_Stock_Master产品维护'!$A$2:$L992,11,FALSE),"No")) -> No | AA14: =IF(G14="","",IFERROR(VLOOKUP(G14,'Product_Stock_Master产品维护'!$A$2:$L992,12,FALSE),""))
A15: 2026-07-15 | C15: Opening | G15: 41-406-00002-00 | H15: =IF(G15="","",IFERROR(VLOOKUP(G15,'Product_Stock_Master产品维护'!$A$2:$E992,2,FALSE()),"SKU not found")) -> H3 Smart遮线罩 | I15: =IF(G15="","",IFERROR(VLOOKUP(G15,'Product_Stock_Master产品维护'!$A$2:$E992,3,FALSE()),"Item type not found")) -> Material | K15: 42 | M15: R1-3-2-R | O15: =IF(C15="","",IF(AND(G15="",NOT(AND(C15="Adjustment_In",P15="Material / 物料"))),"Missing SKU / 缺料号",IF(K15="","Missing Qty / 缺数量",IF(AND(I15="Product",OR(C15="Outbound",C15="Return_to_Repair"),J15=""),"Missing SN for product outbound/return / 成品出库或维修回退缺SN",IF(C15="Move",IF(OR(L15="",M15=""),"Missing Move location / 移库缺来源或目标库位","OK"),IF(OR(C15="Opening",C15="Inbound",C15="Return_to_Repair",C15="Adjustment_In"),IF(M15="","Missing To Location / 缺目标库位","OK"),IF(OR(C15="Outbound",C15="Adjustment_Out",C15="Prepared"),IF(L15="","Missing From Location / 缺来源库位","OK"),"OK"))))))) -> OK | P15: Material / 物料 | Q15: =IF(C15="","",IF(OR(C15="Opening",C15="Inbound",C15="Return_to_Repair",C15="Adjustment_In"),M15,IF(OR(C15="Outbound",C15="Move",C15="Adjustment_Out",C15="Prepared"),L15,""))) -> R1-3-2-R | R15: =IF(C15="","",IF(C15="Return_to_Repair",J15,"")) | S15: =IF(C15="","",IF(C15="Prepared",0,IF(OR(C15="Opening",C15="Inbound",C15="Return_to_Repair",C15="Adjustment_In"),K15,IF(OR(C15="Outbound",C15="Adjustment_Out",C15="Move"),-K15,0)))) -> 42 | T15: =IF(Q15="","",Q15&"|"&F15&"|"&G15&"|"&R15&"|"&P15) -> R1-3-2-R||41-406-00002-00||Material / 物料 | U15: Formula helper / 公式辅助 | V15: Opening balance imported from SYD_Basic_Stock_Capture_Template (1).xlsx | W15: =IF(A15="","",IF(AND(Z15="Yes",P15=""),"Missing stock condition / 缺库存属性",IF(AND(P15="New / 新机",C15="Return_to_Repair"),"New/repair conflict / 新机维修冲突","OK"))) -> OK | X15: =IF(OR(C15="",D15=""),0,IF(COUNTIFS($C$2:C15,C15,$D$2:D15,D15)=1,1,0)) -> 0 | Y15: =IF(AND(C15="Outbound",D15<>"",COUNTIFS($C$2:C15,"Outbound",$D$2:D15,D15)=1,COUNTIFS($C$2:$C1005,"Return_to_Repair",$D$2:$D1005,D15)=0),1,0) -> 0 | Z15: =IF(G15="","",IFERROR(VLOOKUP(G15,'Product_Stock_Master产品维护'!$A$2:$L992,11,FALSE),"No")) -> No | AA15: =IF(G15="","",IFERROR(VLOOKUP(G15,'Product_Stock_Master产品维护'!$A$2:$L992,12,FALSE),""))
A16: 2026-07-15 | C16: Opening | G16: 97-406-00017-00 | H16: =IF(G16="","",IFERROR(VLOOKUP(G16,'Product_Stock_Master产品维护'!$A$2:$E992,2,FALSE()),"SKU not found")) -> KH遮线罩 | I16: =IF(G16="","",IFERROR(VLOOKUP(G16,'Product_Stock_Master产品维护'!$A$2:$E992,3,FALSE()),"Item type not found")) -> Material | K16: 96 | M16: R1-4-2-L | O16: =IF(C16="","",IF(AND(G16="",NOT(AND(C16="Adjustment_In",P16="Material / 物料"))),"Missing SKU / 缺料号",IF(K16="","Missing Qty / 缺数量",IF(AND(I16="Product",OR(C16="Outbound",C16="Return_to_Repair"),J16=""),"Missing SN for product outbound/return / 成品出库或维修回退缺SN",IF(C16="Move",IF(OR(L16="",M16=""),"Missing Move location / 移库缺来源或目标库位","OK"),IF(OR(C16="Opening",C16="Inbound",C16="Return_to_Repair",C16="Adjustment_In"),IF(M16="","Missing To Location / 缺目标库位","OK"),IF(OR(C16="Outbound",C16="Adjustment_Out",C16="Prepared"),IF(L16="","Missing From Location / 缺来源库位","OK"),"OK"))))))) -> OK | P16: Material / 物料 | Q16: =IF(C16="","",IF(OR(C16="Opening",C16="Inbound",C16="Return_to_Repair",C16="Adjustment_In"),M16,IF(OR(C16="Outbound",C16="Move",C16="Adjustment_Out",C16="Prepared"),L16,""))) -> R1-4-2-L | R16: =IF(C16="","",IF(C16="Return_to_Repair",J16,"")) | S16: =IF(C16="","",IF(C16="Prepared",0,IF(OR(C16="Opening",C16="Inbound",C16="Return_to_Repair",C16="Adjustment_In"),K16,IF(OR(C16="Outbound",C16="Adjustment_Out",C16="Move"),-K16,0)))) -> 96 | T16: =IF(Q16="","",Q16&"|"&F16&"|"&G16&"|"&R16&"|"&P16) -> R1-4-2-L||97-406-00017-00||Material / 物料 | U16: Formula helper / 公式辅助 | V16: Opening balance imported from SYD_Basic_Stock_Capture_Template (1).xlsx | W16: =IF(A16="","",IF(AND(Z16="Yes",P16=""),"Missing stock condition / 缺库存属性",IF(AND(P16="New / 新机",C16="Return_to_Repair"),"New/repair conflict / 新机维修冲突","OK"))) -> OK | X16: =IF(OR(C16="",D16=""),0,IF(COUNTIFS($C$2:C16,C16,$D$2:D16,D16)=1,1,0)) -> 0 | Y16: =IF(AND(C16="Outbound",D16<>"",COUNTIFS($C$2:C16,"Outbound",$D$2:D16,D16)=1,COUNTIFS($C$2:$C1006,"Return_to_Repair",$D$2:$D1006,D16)=0),1,0) -> 0 | Z16: =IF(G16="","",IFERROR(VLOOKUP(G16,'Product_Stock_Master产品维护'!$A$2:$L992,11,FALSE),"No")) -> No | AA16: =IF(G16="","",IFERROR(VLOOKUP(G16,'Product_Stock_Master产品维护'!$A$2:$L992,12,FALSE),""))
A17: 2026-07-15 | C17: Opening | G17: 10-120-00471-00 | H17: =IF(G17="","",IFERROR(VLOOKUP(G17,'Product_Stock_Master产品维护'!$A$2:$E992,2,FALSE()),"SKU not found")) -> 保温棉 橡胶泡棉 -90° -180° V-0 黑色 1主8从 上保温棉+下保温棉+四周保温棉(4+5) 带纸箱 | I17: =IF(G17="","",IFERROR(VLOOKUP(G17,'Product_Stock_Master产品维护'!$A$2:$E992,3,FALSE()),"Item type not found")) -> Material | K17: 20 | M17: R1-4-2-R | O17: =IF(C17="","",IF(AND(G17="",NOT(AND(C17="Adjustment_In",P17="Material / 物料"))),"Missing SKU / 缺料号",IF(K17="","Missing Qty / 缺数量",IF(AND(I17="Product",OR(C17="Outbound",C17="Return_to_Repair"),J17=""),"Missing SN for product outbound/return / 成品出库或维修回退缺SN",IF(C17="Move",IF(OR(L17="",M17=""),"Missing Move location / 移库缺来源或目标库位","OK"),IF(OR(C17="Opening",C17="Inbound",C17="Return_to_Repair",C17="Adjustment_In"),IF(M17="","Missing To Location / 缺目标库位","OK"),IF(OR(C17="Outbound",C17="Adjustment_Out",C17="Prepared"),IF(L17="","Missing From Location / 缺来源库位","OK"),"OK"))))))) -> OK | P17: Material / 物料 | Q17: =IF(C17="","",IF(OR(C17="Opening",C17="Inbound",C17="Return_to_Repair",C17="Adjustment_In"),M17,IF(OR(C17="Outbound",C17="Move",C17="Adjustment_Out",C17="Prepared"),L17,""))) -> R1-4-2-R | R17: =IF(C17="","",IF(C17="Return_to_Repair",J17,"")) | S17: =IF(C17="","",IF(C17="Prepared",0,IF(OR(C17="Opening",C17="Inbound",C17="Return_to_Repair",C17="Adjustment_In"),K17,IF(OR(C17="Outbound",C17="Adjustment_Out",C17="Move"),-K17,0)))) -> 20 | T17: =IF(Q17="","",Q17&"|"&F17&"|"&G17&"|"&R17&"|"&P17) -> R1-4-2-R||10-120-00471-00||Material / 物料 | U17: Formula helper / 公式辅助 | V17: Opening balance imported from SYD_Basic_Stock_Capture_Template (1).xlsx | W17: =IF(A17="","",IF(AND(Z17="Yes",P17=""),"Missing stock condition / 缺库存属性",IF(AND(P17="New / 新机",C17="Return_to_Repair"),"New/repair conflict / 新机维修冲突","OK"))) -> OK | X17: =IF(OR(C17="",D17=""),0,IF(COUNTIFS($C$2:C17,C17,$D$2:D17,D17)=1,1,0)) -> 0 | Y17: =IF(AND(C17="Outbound",D17<>"",COUNTIFS($C$2:C17,"Outbound",$D$2:D17,D17)=1,COUNTIFS($C$2:$C1007,"Return_to_Repair",$D$2:$D1007,D17)=0),1,0) -> 0 | Z17: =IF(G17="","",IFERROR(VLOOKUP(G17,'Product_Stock_Master产品维护'!$A$2:$L992,11,FALSE),"No")) | AA17: =IF(G17="","",IFERROR(VLOOKUP(G17,'Product_Stock_Master产品维护'!$A$2:$L992,12,FALSE),""))
A18: 2026-07-15 | C18: Opening | G18: 41-406-00002-00 | H18: =IF(G18="","",IFERROR(VLOOKUP(G18,'Product_Stock_Master产品维护'!$A$2:$E992,2,FALSE()),"SKU not found")) -> H3 Smart遮线罩 | I18: =IF(G18="","",IFERROR(VLOOKUP(G18,'Product_Stock_Master产品维护'!$A$2:$E992,3,FALSE()),"Item type not found")) -> Material | K18: 42 | M18: R1-2-3-L | O18: =IF(C18="","",IF(AND(G18="",NOT(AND(C18="Adjustment_In",P18="Material / 物料"))),"Missing SKU / 缺料号",IF(K18="","Missing Qty / 缺数量",IF(AND(I18="Product",OR(C18="Outbound",C18="Return_to_Repair"),J18=""),"Missing SN for product outbound/return / 成品出库或维修回退缺SN",IF(C18="Move",IF(OR(L18="",M18=""),"Missing Move location / 移库缺来源或目标库位","OK"),IF(OR(C18="Opening",C18="Inbound",C18="Return_to_Repair",C18="Adjustment_In"),IF(M18="","Missing To Location / 缺目标库位","OK"),IF(OR(C18="Outbound",C18="Adjustment_Out",C18="Prepared"),IF(L18="","Missing From Location / 缺来源库位","OK"),"OK"))))))) -> OK | P18: Material / 物料 | Q18: =IF(C18="","",IF(OR(C18="Opening",C18="Inbound",C18="Return_to_Repair",C18="Adjustment_In"),M18,IF(OR(C18="Outbound",C18="Move",C18="Adjustment_Out",C18="Prepared"),L18,""))) -> R1-2-3-L | R18: =IF(C18="","",IF(C18="Return_to_Repair",J18,"")) | S18: =IF(C18="","",IF(C18="Prepared",0,IF(OR(C18="Opening",C18="Inbound",C18="Return_to_Repair",C18="Adjustment_In"),K18,IF(OR(C18="Outbound",C18="Adjustment_Out",C18="Move"),-K18,0)))) -> 42 | T18: =IF(Q18="","",Q18&"|"&F18&"|"&G18&"|"&R18&"|"&P18) -> R1-2-3-L||41-406-00002-00||Material / 物料 | U18: Formula helper / 公式辅助 | V18: Opening balance imported from SYD_Basic_Stock_Capture_Template (1).xlsx | W18: =IF(A18="","",IF(AND(Z18="Yes",P18=""),"Missing stock condition / 缺库存属性",IF(AND(P18="New / 新机",C18="Return_to_Repair"),"New/repair conflict / 新机维修冲突","OK"))) -> OK | X18: =IF(OR(C18="",D18=""),0,IF(COUNTIFS($C$2:C18,C18,$D$2:D18,D18)=1,1,0)) -> 0 | Y18: =IF(AND(C18="Outbound",D18<>"",COUNTIFS($C$2:C18,"Outbound",$D$2:D18,D18)=1,COUNTIFS($C$2:$C1008,"Return_to_Repair",$D$2:$D1008,D18)=0),1,0) -> 0 | Z18: =IF(G18="","",IFERROR(VLOOKUP(G18,'Product_Stock_Master产品维护'!$A$2:$L992,11,FALSE),"No")) -> No | AA18: =IF(G18="","",IFERROR(VLOOKUP(G18,'Product_Stock_Master产品维护'!$A$2:$L992,12,FALSE),""))
A19: 2026-07-17 | C19: Outbound | G19: 41-406-00002-00 | H19: =IF(G19="","",IFERROR(VLOOKUP(G19,'Product_Stock_Master产品维护'!$A$2:$E992,2,FALSE()),"SKU not found")) -> H3 Smart遮线罩 | I19: =IF(G19="","",IFERROR(VLOOKUP(G19,'Product_Stock_Master产品维护'!$A$2:$E992,3,FALSE()),"Item type not found")) -> Material | K19: 42 | L19: R1-2-2-R | O19: =IF(C19="","",IF(AND(G19="",NOT(AND(C19="Adjustment_In",P19="Material / 物料"))),"Missing SKU / 缺料号",IF(K19="","Missing Qty / 缺数量",IF(AND(I19="Product",OR(C19="Outbound",C19="Return_to_Repair"),J19=""),"Missing SN for product outbound/return / 成品出库或维修回退缺SN",IF(C19="Move",IF(OR(L19="",M19=""),"Missing Move location / 移库缺来源或目标库位","OK"),IF(OR(C19="Opening",C19="Inbound",C19="Return_to_Repair",C19="Adjustment_In"),IF(M19="","Missing To Location / 缺目标库位","OK"),IF(OR(C19="Outbound",C19="Adjustment_Out",C19="Prepared"),IF(L19="","Missing From Location / 缺来源库位","OK"),"OK"))))))) -> OK | P19: Material / 物料 | Q19: =IF(C19="","",IF(OR(C19="Opening",C19="Inbound",C19="Return_to_Repair",C19="Adjustment_In"),M19,IF(OR(C19="Outbound",C19="Move",C19="Adjustment_Out",C19="Prepared"),L19,""))) -> R1-2-2-R | R19: =IF(C19="","",IF(C19="Return_to_Repair",J19,"")) | S19: =IF(C19="","",IF(C19="Prepared",0,IF(OR(C19="Opening",C19="Inbound",C19="Return_to_Repair",C19="Adjustment_In"),K19,IF(OR(C19="Outbound",C19="Adjustment_Out",C19="Move"),-K19,0)))) -> -42 | T19: =IF(Q19="","",Q19&"|"&F19&"|"&G19&"|"&R19&"|"&P19) -> R1-2-2-R||41-406-00002-00||Material / 物料 | U19: Formula helper / 公式辅助 | V19: Outbound full qty from R1-2-2-R per request | W19: =IF(A19="","",IF(AND(Z19="Yes",P19=""),"Missing stock condition / 缺库存属性",IF(AND(P19="New / 新机",C19="Return_to_Repair"),"New/repair conflict / 新机维修冲突","OK"))) -> OK | X19: =IF(OR(C19="",D19=""),0,IF(COUNTIFS($C$2:C19,C19,$D$2:D19,D19)=1,1,0)) -> 0 | Y19: =IF(AND(C19="Outbound",D19<>"",COUNTIFS($C$2:C19,"Outbound",$D$2:D19,D19)=1,COUNTIFS($C$2:$C1009,"Return_to_Repair",$D$2:$D1009,D19)=0),1,0) -> 0 | Z19: =IF(G19="","",IFERROR(VLOOKUP(G19,'Product_Stock_Master产品维护'!$A$2:$L992,11,FALSE),"No")) -> No | AA19: =IF(G19="","",IFERROR(VLOOKUP(G19,'Product_Stock_Master产品维护'!$A$2:$L992,12,FALSE),""))
A20: 2026-07-17 | C20: Outbound | G20: 41-406-00002-00 | H20: =IF(G20="","",IFERROR(VLOOKUP(G20,'Product_Stock_Master产品维护'!$A$2:$E992,2,FALSE()),"SKU not found")) -> H3 Smart遮线罩 | I20: =IF(G20="","",IFERROR(VLOOKUP(G20,'Product_Stock_Master产品维护'!$A$2:$E992,3,FALSE()),"Item type not found")) -> Material | K20: 2 | L20: R1-2-2-M | O20: =IF(C20="","",IF(AND(G20="",NOT(AND(C20="Adjustment_In",P20="Material / 物料"))),"Missing SKU / 缺料号",IF(K20="","Missing Qty / 缺数量",IF(AND(I20="Product",OR(C20="Outbound",C20="Return_to_Repair"),J20=""),"Missing SN for product outbound/return / 成品出库或维修回退缺SN",IF(C20="Move",IF(OR(L20="",M20=""),"Missing Move location / 移库缺来源或目标库位","OK"),IF(OR(C20="Opening",C20="Inbound",C20="Return_to_Repair",C20="Adjustment_In"),IF(M20="","Missing To Location / 缺目标库位","OK"),IF(OR(C20="Outbound",C20="Adjustment_Out",C20="Prepared"),IF(L20="","Missing From Location / 缺来源库位","OK"),"OK"))))))) -> OK | P20: Material / 物料 | Q20: =IF(C20="","",IF(OR(C20="Opening",C20="Inbound",C20="Return_to_Repair",C20="Adjustment_In"),M20,IF(OR(C20="Outbound",C20="Move",C20="Adjustment_Out",C20="Prepared"),L20,""))) -> R1-2-2-M | R20: =IF(C20="","",IF(C20="Return_to_Repair",J20,"")) | S20: =IF(C20="","",IF(C20="Prepared",0,IF(OR(C20="Opening",C20="Inbound",C20="Return_to_Repair",C20="Adjustment_In"),K20,IF(OR(C20="Outbound",C20="Adjustment_Out",C20="Move"),-K20,0)))) -> -2 | T20: =IF(Q20="","",Q20&"|"&F20&"|"&G20&"|"&R20&"|"&P20) -> R1-2-2-M||41-406-00002-00||Material / 物料 | U20: Formula helper / 公式辅助 | V20: Outbound 2 qty from R1-2-2-M per request | W20: =IF(A20="","",IF(AND(Z20="Yes",P20=""),"Missing stock condition / 缺库存属性",IF(AND(P20="New / 新机",C20="Return_to_Repair"),"New/repair conflict / 新机维修冲突","OK"))) -> OK | X20: =IF(OR(C20="",D20=""),0,IF(COUNTIFS($C$2:C20,C20,$D$2:D20,D20)=1,1,0)) -> 0 | Y20: =IF(AND(C20="Outbound",D20<>"",COUNTIFS($C$2:C20,"Outbound",$D$2:D20,D20)=1,COUNTIFS($C$2:$C1010,"Return_to_Repair",$D$2:$D1010,D20)=0),1,0) -> 0 | Z20: =IF(G20="","",IFERROR(VLOOKUP(G20,'Product_Stock_Master产品维护'!$A$2:$L992,11,FALSE),"No")) -> No | AA20: =IF(G20="","",IFERROR(VLOOKUP(G20,'Product_Stock_Master产品维护'!$A$2:$L992,12,FALSE),""))
A21: 2026-07-20 | C21: Outbound | G21: 41-406-00002-00 | H21: =IF(G21="","",IFERROR(VLOOKUP(G21,'Product_Stock_Master产品维护'!$A$2:$E992,2,FALSE()),"SKU not found")) -> H3 Smart遮线罩 | I21: =IF(G21="","",IFERROR(VLOOKUP(G21,'Product_Stock_Master产品维护'!$A$2:$E992,3,FALSE()),"Item type not found")) -> Material | K21: 42 | L21: R1-2-1-R | O21: =IF(C21="","",IF(AND(G21="",NOT(AND(C21="Adjustment_In",P21="Material / 物料"))),"Missing SKU / 缺料号",IF(K21="","Missing Qty / 缺数量",IF(AND(I21="Product",OR(C21="Outbound",C21="Return_to_Repair"),J21=""),"Missing SN for product outbound/return / 成品出库或维修回退缺SN",IF(C21="Move",IF(OR(L21="",M21=""),"Missing Move location / 移库缺来源或目标库位","OK"),IF(OR(C21="Opening",C21="Inbound",C21="Return_to_Repair",C21="Adjustment_In"),IF(M21="","Missing To Location / 缺目标库位","OK"),IF(OR(C21="Outbound",C21="Adjustment_Out",C21="Prepared"),IF(L21="","Missing From Location / 缺来源库位","OK"),"OK"))))))) -> OK | P21: Material / 物料 | Q21: =IF(C21="","",IF(OR(C21="Opening",C21="Inbound",C21="Return_to_Repair",C21="Adjustment_In"),M21,IF(OR(C21="Outbound",C21="Move",C21="Adjustment_Out",C21="Prepared"),L21,""))) -> R1-2-1-R | R21: =IF(C21="","",IF(C21="Return_to_Repair",J21,"")) | S21: =IF(C21="","",IF(C21="Prepared",0,IF(OR(C21="Opening",C21="Inbound",C21="Return_to_Repair",C21="Adjustment_In"),K21,IF(OR(C21="Outbound",C21="Adjustment_Out",C21="Move"),-K21,0)))) -> -42 | T21: =IF(Q21="","",Q21&"|"&F21&"|"&G21&"|"&R21&"|"&P21) -> R1-2-1-R||41-406-00002-00||Material / 物料 | U21: Formula helper / 公式辅助 | V21: Outbound remaining qty from R1-2-1-R per request | W21: =IF(A21="","",IF(AND(Z21="Yes",P21=""),"Missing stock condition / 缺库存属性",IF(AND(P21="New / 新机",C21="Return_to_Repair"),"New/repair conflict / 新机维修冲突","OK"))) -> OK | X21: =IF(OR(C21="",D21=""),0,IF(COUNTIFS($C$2:C21,C21,$D$2:D21,D21)=1,1,0)) -> 0 | Y21: =IF(AND(C21="Outbound",D21<>"",COUNTIFS($C$2:C21,"Outbound",$D$2:D21,D21)=1,COUNTIFS($C$2:$C1011,"Return_to_Repair",$D$2:$D1011,D21)=0),1,0) -> 0 | Z21: =IF(G21="","",IFERROR(VLOOKUP(G21,'Product_Stock_Master产品维护'!$A$2:$L992,11,FALSE),"No")) -> No | AA21: =IF(G21="","",IFERROR(VLOOKUP(G21,'Product_Stock_Master产品维护'!$A$2:$L992,12,FALSE),""))
A22: 2026-07-20 | C22: Outbound | G22: 41-406-00002-00 | H22: =IF(G22="","",IFERROR(VLOOKUP(G22,'Product_Stock_Master产品维护'!$A$2:$E992,2,FALSE()),"SKU not found")) -> H3 Smart遮线罩 | I22: =IF(G22="","",IFERROR(VLOOKUP(G22,'Product_Stock_Master产品维护'!$A$2:$E992,3,FALSE()),"Item type not found")) -> Material | K22: 42 | L22: R1-2-2-L | O22: =IF(C22="","",IF(AND(G22="",NOT(AND(C22="Adjustment_In",P22="Material / 物料"))),"Missing SKU / 缺料号",IF(K22="","Missing Qty / 缺数量",IF(AND(I22="Product",OR(C22="Outbound",C22="Return_to_Repair"),J22=""),"Missing SN for product outbound/return / 成品出库或维修回退缺SN",IF(C22="Move",IF(OR(L22="",M22=""),"Missing Move location / 移库缺来源或目标库位","OK"),IF(OR(C22="Opening",C22="Inbound",C22="Return_to_Repair",C22="Adjustment_In"),IF(M22="","Missing To Location / 缺目标库位","OK"),IF(OR(C22="Outbound",C22="Adjustment_Out",C22="Prepared"),IF(L22="","Missing From Location / 缺来源库位","OK"),"OK"))))))) -> OK | P22: Material / 物料 | Q22: =IF(C22="","",IF(OR(C22="Opening",C22="Inbound",C22="Return_to_Repair",C22="Adjustment_In"),M22,IF(OR(C22="Outbound",C22="Move",C22="Adjustment_Out",C22="Prepared"),L22,""))) -> R1-2-2-L | R22: =IF(C22="","",IF(C22="Return_to_Repair",J22,"")) | S22: =IF(C22="","",IF(C22="Prepared",0,IF(OR(C22="Opening",C22="Inbound",C22="Return_to_Repair",C22="Adjustment_In"),K22,IF(OR(C22="Outbound",C22="Adjustment_Out",C22="Move"),-K22,0)))) -> -42 | T22: =IF(Q22="","",Q22&"|"&F22&"|"&G22&"|"&R22&"|"&P22) -> R1-2-2-L||41-406-00002-00||Material / 物料 | U22: Formula helper / 公式辅助 | V22: Outbound remaining qty from R1-2-2-L per request | W22: =IF(A22="","",IF(AND(Z22="Yes",P22=""),"Missing stock condition / 缺库存属性",IF(AND(P22="New / 新机",C22="Return_to_Repair"),"New/repair conflict / 新机维修冲突","OK"))) -> OK | X22: =IF(OR(C22="",D22=""),0,IF(COUNTIFS($C$2:C22,C22,$D$2:D22,D22)=1,1,0)) -> 0 | Y22: =IF(AND(C22="Outbound",D22<>"",COUNTIFS($C$2:C22,"Outbound",$D$2:D22,D22)=1,COUNTIFS($C$2:$C1012,"Return_to_Repair",$D$2:$D1012,D22)=0),1,0) -> 0 | Z22: =IF(G22="","",IFERROR(VLOOKUP(G22,'Product_Stock_Master产品维护'!$A$2:$L992,11,FALSE),"No")) -> No | AA22: =IF(G22="","",IFERROR(VLOOKUP(G22,'Product_Stock_Master产品维护'!$A$2:$L992,12,FALSE),""))
A23: 2026-07-20 | C23: Outbound | G23: 41-406-00002-00 | H23: =IF(G23="","",IFERROR(VLOOKUP(G23,'Product_Stock_Master产品维护'!$A$2:$E992,2,FALSE()),"SKU not found")) -> H3 Smart遮线罩 | I23: =IF(G23="","",IFERROR(VLOOKUP(G23,'Product_Stock_Master产品维护'!$A$2:$E992,3,FALSE()),"Item type not found")) -> Material | K23: 40 | L23: R1-2-2-M | O23: =IF(C23="","",IF(AND(G23="",NOT(AND(C23="Adjustment_In",P23="Material / 物料"))),"Missing SKU / 缺料号",IF(K23="","Missing Qty / 缺数量",IF(AND(I23="Product",OR(C23="Outbound",C23="Return_to_Repair"),J23=""),"Missing SN for product outbound/return / 成品出库或维修回退缺SN",IF(C23="Move",IF(OR(L23="",M23=""),"Missing Move location / 移库缺来源或目标库位","OK"),IF(OR(C23="Opening",C23="Inbound",C23="Return_to_Repair",C23="Adjustment_In"),IF(M23="","Missing To Location / 缺目标库位","OK"),IF(OR(C23="Outbound",C23="Adjustment_Out",C23="Prepared"),IF(L23="","Missing From Location / 缺来源库位","OK"),"OK"))))))) -> OK | P23: Material / 物料 | Q23: =IF(C23="","",IF(OR(C23="Opening",C23="Inbound",C23="Return_to_Repair",C23="Adjustment_In"),M23,IF(OR(C23="Outbound",C23="Move",C23="Adjustment_Out",C23="Prepared"),L23,""))) -> R1-2-2-M | R23: =IF(C23="","",IF(C23="Return_to_Repair",J23,"")) | S23: =IF(C23="","",IF(C23="Prepared",0,IF(OR(C23="Opening",C23="Inbound",C23="Return_to_Repair",C23="Adjustment_In"),K23,IF(OR(C23="Outbound",C23="Adjustment_Out",C23="Move"),-K23,0)))) -> -40 | T23: =IF(Q23="","",Q23&"|"&F23&"|"&G23&"|"&R23&"|"&P23) -> R1-2-2-M||41-406-00002-00||Material / 物料 | U23: Formula helper / 公式辅助 | V23: Outbound remaining qty from R1-2-2-M per request | W23: =IF(A23="","",IF(AND(Z23="Yes",P23=""),"Missing stock condition / 缺库存属性",IF(AND(P23="New / 新机",C23="Return_to_Repair"),"New/repair conflict / 新机维修冲突","OK"))) -> OK | X23: =IF(OR(C23="",D23=""),0,IF(COUNTIFS($C$2:C23,C23,$D$2:D23,D23)=1,1,0)) -> 0 | Y23: =IF(AND(C23="Outbound",D23<>"",COUNTIFS($C$2:C23,"Outbound",$D$2:D23,D23)=1,COUNTIFS($C$2:$C1013,"Return_to_Repair",$D$2:$D1013,D23)=0),1,0) -> 0 | Z23: =IF(G23="","",IFERROR(VLOOKUP(G23,'Product_Stock_Master产品维护'!$A$2:$L992,11,FALSE),"No")) -> No | AA23: =IF(G23="","",IFERROR(VLOOKUP(G23,'Product_Stock_Master产品维护'!$A$2:$L992,12,FALSE),""))
A24: 2026-07-21 | C24: Outbound | G24: 97-406-00017-00 | H24: =IF(G24="","",IFERROR(VLOOKUP(G24,'Product_Stock_Master产品维护'!$A$2:$E992,2,FALSE()),"SKU not found")) -> KH遮线罩 | I24: =IF(G24="","",IFERROR(VLOOKUP(G24,'Product_Stock_Master产品维护'!$A$2:$E992,3,FALSE()),"Item type not found")) -> Material | K24: 96 | L24: R1-4-1-L | O24: =IF(C24="","",IF(AND(G24="",NOT(AND(C24="Adjustment_In",P24="Material / 物料"))),"Missing SKU / 缺料号",IF(K24="","Missing Qty / 缺数量",IF(AND(I24="Product",OR(C24="Outbound",C24="Return_to_Repair"),J24=""),"Missing SN for product outbound/return / 成品出库或维修回退缺SN",IF(C24="Move",IF(OR(L24="",M24=""),"Missing Move location / 移库缺来源或目标库位","OK"),IF(OR(C24="Opening",C24="Inbound",C24="Return_to_Repair",C24="Adjustment_In"),IF(M24="","Missing To Location / 缺目标库位","OK"),IF(OR(C24="Outbound",C24="Adjustment_Out",C24="Prepared"),IF(L24="","Missing From Location / 缺来源库位","OK"),"OK"))))))) -> OK | P24: Material / 物料 | Q24: =IF(C24="","",IF(OR(C24="Opening",C24="Inbound",C24="Return_to_Repair",C24="Adjustment_In"),M24,IF(OR(C24="Outbound",C24="Move",C24="Adjustment_Out",C24="Prepared"),L24,""))) -> R1-4-1-L | R24: =IF(C24="","",IF(C24="Return_to_Repair",J24,"")) | S24: =IF(C24="","",IF(C24="Prepared",0,IF(OR(C24="Opening",C24="Inbound",C24="Return_to_Repair",C24="Adjustment_In"),K24,IF(OR(C24="Outbound",C24="Adjustment_Out",C24="Move"),-K24,0)))) -> -96 | T24: =IF(Q24="","",Q24&"|"&F24&"|"&G24&"|"&R24&"|"&P24) -> R1-4-1-L||97-406-00017-00||Material / 物料 | U24: Formula helper / 公式辅助 | V24: Outbound remaining qty from R1-4-1-L per request | W24: =IF(A24="","",IF(AND(Z24="Yes",P24=""),"Missing stock condition / 缺库存属性",IF(AND(P24="New / 新机",C24="Return_to_Repair"),"New/repair conflict / 新机维修冲突","OK"))) -> OK | X24: =IF(OR(C24="",D24=""),0,IF(COUNTIFS($C$2:C24,C24,$D$2:D24,D24)=1,1,0)) -> 0 | Y24: =IF(AND(C24="Outbound",D24<>"",COUNTIFS($C$2:C24,"Outbound",$D$2:D24,D24)=1,COUNTIFS($C$2:$C1014,"Return_to_Repair",$D$2:$D1014,D24)=0),1,0) -> 0 | Z24: =IF(G24="","",IFERROR(VLOOKUP(G24,'Product_Stock_Master产品维护'!$A$2:$L992,11,FALSE),"No")) -> No | AA24: =IF(G24="","",IFERROR(VLOOKUP(G24,'Product_Stock_Master产品维护'!$A$2:$L992,12,FALSE),""))
A25: 2026-07-21 | C25: Outbound | G25: 97-406-00017-00 | H25: =IF(G25="","",IFERROR(VLOOKUP(G25,'Product_Stock_Master产品维护'!$A$2:$E992,2,FALSE()),"SKU not found")) -> KH遮线罩 | I25: =IF(G25="","",IFERROR(VLOOKUP(G25,'Product_Stock_Master产品维护'!$A$2:$E992,3,FALSE()),"Item type not found")) -> Material | K25: 96 | L25: R1-4-2-L | O25: =IF(C25="","",IF(AND(G25="",NOT(AND(C25="Adjustment_In",P25="Material / 物料"))),"Missing SKU / 缺料号",IF(K25="","Missing Qty / 缺数量",IF(AND(I25="Product",OR(C25="Outbound",C25="Return_to_Repair"),J25=""),"Missing SN for product outbound/return / 成品出库或维修回退缺SN",IF(C25="Move",IF(OR(L25="",M25=""),"Missing Move location / 移库缺来源或目标库位","OK"),IF(OR(C25="Opening",C25="Inbound",C25="Return_to_Repair",C25="Adjustment_In"),IF(M25="","Missing To Location / 缺目标库位","OK"),IF(OR(C25="Outbound",C25="Adjustment_Out",C25="Prepared"),IF(L25="","Missing From Location / 缺来源库位","OK"),"OK"))))))) -> OK | P25: Material / 物料 | Q25: =IF(C25="","",IF(OR(C25="Opening",C25="Inbound",C25="Return_to_Repair",C25="Adjustment_In"),M25,IF(OR(C25="Outbound",C25="Move",C25="Adjustment_Out",C25="Prepared"),L25,""))) -> R1-4-2-L | R25: =IF(C25="","",IF(C25="Return_to_Repair",J25,"")) | S25: =IF(C25="","",IF(C25="Prepared",0,IF(OR(C25="Opening",C25="Inbound",C25="Return_to_Repair",C25="Adjustment_In"),K25,IF(OR(C25="Outbound",C25="Adjustment_Out",C25="Move"),-K25,0)))) -> -96 | T25: =IF(Q25="","",Q25&"|"&F25&"|"&G25&"|"&R25&"|"&P25) -> R1-4-2-L||97-406-00017-00||Material / 物料 | U25: Formula helper / 公式辅助 | V25: Outbound remaining qty from R1-4-2-L per request | W25: =IF(A25="","",IF(AND(Z25="Yes",P25=""),"Missing stock condition / 缺库存属性",IF(AND(P25="New / 新机",C25="Return_to_Repair"),"New/repair conflict / 新机维修冲突","OK"))) -> OK | X25: =IF(OR(C25="",D25=""),0,IF(COUNTIFS($C$2:C25,C25,$D$2:D25,D25)=1,1,0)) -> 0 | Y25: =IF(AND(C25="Outbound",D25<>"",COUNTIFS($C$2:C25,"Outbound",$D$2:D25,D25)=1,COUNTIFS($C$2:$C1015,"Return_to_Repair",$D$2:$D1015,D25)=0),1,0) -> 0 | Z25: =IF(G25="","",IFERROR(VLOOKUP(G25,'Product_Stock_Master产品维护'!$A$2:$L992,11,FALSE),"No")) -> No | AA25: =IF(G25="","",IFERROR(VLOOKUP(G25,'Product_Stock_Master产品维护'!$A$2:$L992,12,FALSE),""))
A26: 2026-07-21 | C26: Outbound | G26: 41-406-00002-00 | H26: =IF(G26="","",IFERROR(VLOOKUP(G26,'Product_Stock_Master产品维护'!$A$2:$E992,2,FALSE()),"SKU not found")) -> H3 Smart遮线罩 | I26: =IF(G26="","",IFERROR(VLOOKUP(G26,'Product_Stock_Master产品维护'!$A$2:$E992,3,FALSE()),"Item type not found")) -> Material | K26: 42 | L26: R1-3-1-M | O26: =IF(C26="","",IF(AND(G26="",NOT(AND(C26="Adjustment_In",P26="Material / 物料"))),"Missing SKU / 缺料号",IF(K26="","Missing Qty / 缺数量",IF(AND(I26="Product",OR(C26="Outbound",C26="Return_to_Repair"),J26=""),"Missing SN for product outbound/return / 成品出库或维修回退缺SN",IF(C26="Move",IF(OR(L26="",M26=""),"Missing Move location / 移库缺来源或目标库位","OK"),IF(OR(C26="Opening",C26="Inbound",C26="Return_to_Repair",C26="Adjustment_In"),IF(M26="","Missing To Location / 缺目标库位","OK"),IF(OR(C26="Outbound",C26="Adjustment_Out",C26="Prepared"),IF(L26="","Missing From Location / 缺来源库位","OK"),"OK"))))))) -> OK | P26: Material / 物料 | Q26: =IF(C26="","",IF(OR(C26="Opening",C26="Inbound",C26="Return_to_Repair",C26="Adjustment_In"),M26,IF(OR(C26="Outbound",C26="Move",C26="Adjustment_Out",C26="Prepared"),L26,""))) -> R1-3-1-M | R26: =IF(C26="","",IF(C26="Return_to_Repair",J26,"")) | S26: =IF(C26="","",IF(C26="Prepared",0,IF(OR(C26="Opening",C26="Inbound",C26="Return_to_Repair",C26="Adjustment_In"),K26,IF(OR(C26="Outbound",C26="Adjustment_Out",C26="Move"),-K26,0)))) -> -42 | T26: =IF(Q26="","",Q26&"|"&F26&"|"&G26&"|"&R26&"|"&P26) -> R1-3-1-M||41-406-00002-00||Material / 物料 | U26: Formula helper / 公式辅助 | V26: Outbound remaining qty from R1-3-1-M per request | W26: =IF(A26="","",IF(AND(Z26="Yes",P26=""),"Missing stock condition / 缺库存属性",IF(AND(P26="New / 新机",C26="Return_to_Repair"),"New/repair conflict / 新机维修冲突","OK"))) -> OK | X26: =IF(OR(C26="",D26=""),0,IF(COUNTIFS($C$2:C26,C26,$D$2:D26,D26)=1,1,0)) -> 0 | Y26: =IF(AND(C26="Outbound",D26<>"",COUNTIFS($C$2:C26,"Outbound",$D$2:D26,D26)=1,COUNTIFS($C$2:$C1016,"Return_to_Repair",$D$2:$D1016,D26)=0),1,0) -> 0 | Z26: =IF(G26="","",IFERROR(VLOOKUP(G26,'Product_Stock_Master产品维护'!$A$2:$L992,11,FALSE),"No")) -> No | AA26: =IF(G26="","",IFERROR(VLOOKUP(G26,'Product_Stock_Master产品维护'!$A$2:$L992,12,FALSE),""))
